<?xml version="1.0" encoding="utf-8"?>
<robot xmlns:xacro="http://www.ros.org/wiki/xacro" name="hand">
  <xacro:macro name="hand" params="connected_to:='' ns:='' rpy:='0 0 0' xyz:='0 0 0' ">
    <xacro:unless value="${connected_to == ''}">
      <joint name="${ns}_hand_joint" type="fixed">
        <parent link="${connected_to}"/>
        <child link="${ns}_hand"/>
        <origin xyz="${xyz}" rpy="${rpy}"/>
      </joint>
    </xacro:unless>
  <link
    name="${ns}_hand">
    <inertial>
      <origin
        xyz="0 -6.93889390390723E-18 0.0150172297115083"
        rpy="0 0 0" />
      <mass
        value="0.0547007330603109" />
      <inertia
        ixx="3.82502607446515E-05"
        ixy="5.63004985316599E-13"
        ixz="1.38024178340574E-21"
        iyy="2.55682822465902E-05"
        iyz="-2.99181481392226E-21"
        izz="3.01786195512601E-05" />
    </inertial>
    <visual>
      <origin
        xyz="0 0 0"
        rpy="0 0 0" />
      <geometry>
        <mesh
          filename="package://urdf_gripper1/meshes/Link_1.stl" />
      </geometry>
      <material
        name="">
        <color
          rgba="0.752941176470588 0.752941176470588 0.752941176470588 1" />
      </material>
    </visual>
    <collision>
      <origin
        xyz="0 0 0"
        rpy="0 0 0" />
      <geometry>
        <mesh
          filename="package://urdf_gripper1/meshes/Link_1.stl" />
      </geometry>
    </collision>
  </link>
  <link
    name="Link_2">
    <inertial>
      <origin
        xyz="0.000133911513531482 0.0308660885322123 0.0108576264680072"
        rpy="0 0 0" />
      <mass value="0.098997" />
        <inertia ixx="0.0000276300" ixy="0.0000000418" ixz="0.0000005145" iyy="0.0000204300" iyz="-0.0000000421" izz="0.0000276300"/>
    </inertial>
    <visual>
      <origin
        xyz="0 0 0"
        rpy="0 0 0" />
      <geometry>
        <mesh
          filename="package://urdf_gripper1/meshes/Link_2.stl" />
      </geometry>
      <material
        name="">
        <color
          rgba="0.752941176470588 0.752941176470588 0.752941176470588 1" />
      </material>
    </visual>
    <collision>
      <origin
        xyz="0 0 0"
        rpy="0 0 0" />
      <geometry>
        <mesh
          filename="package://urdf_gripper1/meshes/Link_2.stl" scale="0.6 0.6 0.6" />
      </geometry>
    </collision>
  </link>
  <joint
    name="Joint_1"
    type="continuous">
    <origin
      xyz="0 -0.031 0.029"
      rpy="0 0 0" />
    <limit effort="0.35" lower="-0.524" upper="0.524" velocity="6.283"/>
    <parent
      link="${ns}_hand" />
    <child
      link="Link_2" />
    <axis
      xyz="0 0 1" />
  </joint>
  <link
    name="Link_3">
    <inertial>
      <origin
        xyz="-6.6959E-10 -0.047312 -0.003167"
        rpy="0 0 0" />
      <mass
        value="0.035188" />
      <inertia
        ixx="3.0041E-05"
        ixy="3.5933E-13"
        ixz="2.5652E-13"
        iyy="1.7697E-05"
        iyz="-2.3365E-07"
        izz="4.1102E-05" />
    </inertial>
    <visual>
      <origin
        xyz="0 0 0"
        rpy="0 0 0" />
      <geometry>
        <mesh
          filename="package://urdf_gripper1/meshes/Link_3.stl" />
      </geometry>
      <material
        name="">
        <color
          rgba="0.75294 0.75294 0.75294 1" />
      </material>
    </visual>
    <collision>
      <origin
        xyz="0 0 0"
        rpy="0 0 0" />
      <geometry>
        <mesh
          filename="package://urdf_gripper1/meshes/Link_3.stl" />
      </geometry>
    </collision>
  </link>
  <joint
    name="Joint_2"
    type="continuous">
    <origin
      xyz="0 -0.024 0"
      rpy="0 0 0" />
    <limit effort="0.35" lower="-1.57" upper="0.0" velocity="6.283"/>
    <parent
      link="Link_2" />
    <child
      link="Link_3" />
    <axis
      xyz="1 0 0" />
  </joint>
  <link
    name="Link_4">
    <inertial>
      <origin
        xyz="0.00013391 0.15039 0.010104"
        rpy="0 0 0" />
      <mass value="0.098997" />
        <inertia ixx="0.0000276300" ixy="0.0000000418" ixz="0.0000005145" iyy="0.0000204300" iyz="-0.0000000421" izz="0.0000276300"/>
    </inertial>
    <visual>
      <origin
        xyz="0 0 0"
        rpy="0 0 0" />
      <geometry>
        <mesh
          filename="package://urdf_gripper1/meshes/Link_4.stl" scale="0.95 0.95 0.95"/>
      </geometry>
      <material
        name="">
        <color
          rgba="0.75294 0.75294 0.75294 1" />
      </material>
    </visual>
    <collision>
      <origin
        xyz="0 0 0"
        rpy="0 0 0" />
      <geometry>
        <mesh
          filename="package://urdf_gripper1/meshes/Link_4.stl" scale="0.6 0.6 0.6" />
      </geometry>
    </collision>
  </link>
  <joint
    name="Joint_3"
    type="continuous">
    <origin
      xyz="0 -0.095522 0.000754"
      rpy="0 0 0" />
    <limit effort="0.35" lower="0.6" upper="2.2" velocity="6.283"/>
    <parent
      link="Link_3" />
    <child
      link="Link_4" />
    <axis
      xyz="1 0 0" />
  </joint>
  <link
    name="Grip_1">
    <inertial>
      <origin
        xyz="-1.87532538448026E-05 -1.46755248142255E-05 0.0353004822904477"
        rpy="0 0 0" />
      <mass
        value="0.0344208838298377" />
      <inertia
        ixx="7.7154399626129E-06"
        ixy="2.6075628479324E-10"
        ixz="1.58733850084192E-09"
        iyy="4.43641994241611E-06"
        iyz="1.64596780856448E-10"
        izz="7.87085677073128E-06" />
    </inertial>
    <visual>
      <origin
        xyz="0 0 0"
        rpy="0 0 0" />
      <geometry>
        <mesh
          filename="package://urdf_gripper1/meshes/Grip_1.stl" />
      </geometry>
      <material
        name="">
        <color
          rgba="0.752941176470588 0.752941176470588 0.752941176470588 1" />
      </material>
    </visual>
    <collision>
      <origin
        xyz="0 0 0"
        rpy="0 0 0" />
      <geometry>
        <mesh
          filename="package://urdf_gripper1/meshes/Grip_1.stl" />
      </geometry>
    </collision>
  </link>
  <joint
    name="Joint_4"
    type="continuous">
    <origin
      xyz="0 0 0.024"
      rpy="0 0 0" />
    <limit effort="0.35" lower="-1.22" upper="1.22" velocity="6.283"/>
    <parent
      link="Link_4" />
    <child
      link="Grip_1" />
    <axis
      xyz="0 1 0" />
  </joint>
  <link
    name="Link_5">
    <inertial>
      <origin
        xyz="0 0 0"
        rpy="0 0 0" />
      <mass value="0.098997" />
        <inertia ixx="0.0000276300" ixy="0.0000000418" ixz="0.0000005145" iyy="0.0000204300" iyz="-0.0000000421" izz="0.0000276300"/>
    </inertial>
    <visual>
      <origin
        xyz="0 0 0"
        rpy="0 0 0" />
      <geometry>
        <mesh
          filename="package://urdf_gripper1/meshes/Link_5.stl" />
      </geometry>
      <material
        name="">
        <color
          rgba="1 1 1 1" />
      </material>
    </visual>
    <collision>
      <origin
        xyz="0 0 0"
        rpy="0 0 0" />
      <geometry>
        <mesh
          filename="package://urdf_gripper1/meshes/Link_5.stl" scale="0.6 0.6 0.6" />
      </geometry>
    </collision>
  </link>
  <joint
    name="Joint_5"
    type="continuous">
    <origin
      xyz="0 0.031 0.029"
      rpy="0 0 0" />
    <limit effort="0.35" lower="-0.524" upper="0.524" velocity="6.283"/>
    <parent
      link="${ns}_hand" />
    <child
      link="Link_5" />
    <axis
      xyz="0 0 1" />
  </joint>
  <link
    name="Link_6">
    <inertial>
      <origin
        xyz="6.69590480284477E-10 0.047312259543009 -0.00316696601621572"
        rpy="0 0 0" />
      <mass
        value="0.0351877222430874" />
      <inertia
        ixx="3.00405223867073E-05"
        ixy="3.59327904026506E-13"
        ixz="-2.56522219181268E-13"
        iyy="1.76968982571648E-05"
        iyz="2.33648286999841E-07"
        izz="4.11020098914542E-05" />
    </inertial>
    <visual>
      <origin
        xyz="0 0 0"
        rpy="0 0 0" />
      <geometry>
        <mesh
          filename="package://urdf_gripper1/meshes/Link_6.stl" />
      </geometry>
      <material
        name="">
        <color
          rgba="0.752941176470588 0.752941176470588 0.752941176470588 1" />
      </material>
    </visual>
    <collision>
      <origin
        xyz="0 0 0"
        rpy="0 0 0" />
      <geometry>
        <mesh
          filename="package://urdf_gripper1/meshes/Link_6.stl" />
      </geometry>
    </collision>
  </link>
  <joint
    name="Joint_6"
    type="continuous">
    <origin
      xyz="0 0.024 0"
      rpy="0 0 0" />
    <limit effort="0.35" lower="0.0" upper="1.57" velocity="6.283"/>
    <parent
      link="Link_5" />
    <child
      link="Link_6" />
    <axis
      xyz="1 0 0" />
  </joint>
  <link
    name="Link_7">
    <inertial>
      <origin
        xyz="0.000133910925717962 -0.150655801871864 0.0101036224635462"
        rpy="0 0 0" />
      <mass value="0.098997" />
        <inertia ixx="0.0000276300" ixy="0.0000000418" ixz="0.0000005145" iyy="0.0000204300" iyz="-0.0000000421" izz="0.0000276300"/>
    </inertial>
    <visual>
      <origin
        xyz="0 0 0"
        rpy="0 0 0" />
      <geometry>
        <mesh
          filename="package://urdf_gripper1/meshes/Link_7.stl" scale="0.95 0.95 0.95" />
      </geometry>
      <material
        name="">
        <color
          rgba="0.752941176470588 0.752941176470588 0.752941176470588 1" />
      </material>
    </visual>
    <collision>
      <origin
        xyz="0 0 0"
        rpy="0 0 0" />
      <geometry>
        <mesh
          filename="package://urdf_gripper1/meshes/Link_7.stl" scale="0.6 0.6 0.6" />
      </geometry>
    </collision>
  </link>
  <joint
    name="Joint_7"
    type="continuous">
    <origin
      xyz="0 0.095522 0.000754"
      rpy="0 0 0" />
    <limit effort="0.35" lower="-2.2" upper="-0.6" velocity="6.283"/>
    <parent
      link="Link_6" />
    <child
      link="Link_7" />
    <axis
      xyz="1 0 0" />
  </joint>
  <link
    name="Grip_2">
    <inertial>
      <origin
        xyz="1.87532538436924E-05 1.46755248140451E-05 0.0363332648225437"
        rpy="0 0 0" />
      <mass
        value="0.0344208838298375" />
      <inertia
        ixx="7.71543996261288E-06"
        ixy="2.60756284790869E-10"
        ixz="-1.58733850085364E-09"
        iyy="4.43641994241609E-06"
        iyz="-1.64596780858671E-10"
        izz="7.87085677073125E-06" />
    </inertial>
    <visual>
      <origin
        xyz="0 0 0"
        rpy="0 0 0" />
      <geometry>
        <mesh
          filename="package://urdf_gripper1/meshes/Grip_2.stl" />
      </geometry>
      <material
        name="">
        <color
          rgba="0.752941176470588 0.752941176470588 0.752941176470588 1" />
      </material>
    </visual>
    <collision>
      <origin
        xyz="0 0 0"
        rpy="0 0 0" />
      <geometry>
        <mesh
          filename="package://urdf_gripper1/meshes/Grip_2.stl" />
      </geometry>
    </collision>
  </link>
  <joint
    name="Joint_8"
    type="continuous">
    <origin
      xyz="0 0 0.024"
      rpy="0 0 0" />
    <limit effort="0.35" lower="-1.22" upper="1.22" velocity="6.283"/>
    <parent
      link="Link_7" />
    <child
      link="Grip_2" />
    <axis
      xyz="0 1 0" />
  </joint>
  </xacro:macro>
</robot>

